<?xml version="1.0" ?>
<!-- =================================================================================== -->
<!-- |    This document was autogenerated by xacro from src/robotiq/robotiq_2f_140_gripper_visualization/urdf/robotiq_arg2f_140_model.xacro | -->
<!-- |    EDITING THIS FILE BY HAND IS NOT RECOMMENDED                                 | -->
<!-- =================================================================================== -->
<robot name="robotiq_arg2f_140_model" xmlns:xacro="http://ros.org/wiki/xacro">
  <link name="robotiq_arg2f_base_link">
    <inertial>
      <origin rpy="0 0 0" xyz="1.8086e-07 -9.683e-05 0.035953"/>
      <mass value="0.22652"/>
      <inertia ixx="0.00020362" ixy="9.3277e-12" ixz="1.4059e-09" iyy="0.00017774" iyz="-8.1406e-07" izz="0.00014377"/>
    </inertial>
    <visual>
      <origin rpy="0 0 0" xyz="0 0 0"/>
      <geometry>
        <mesh filename="/home/dan/Projects/DrakeForks/VanillaDrakeWithIssue19842Mods/drake/examples/simple_gripper/robotiq_2f_140_gripper/visual/robotiq_arg2f_base_link.obj"/>
      </geometry>
      <material name="">
        <color rgba="0.1 0.1 0.1 1"/>
      </material>
    </visual>
    <collision>
      <origin rpy="0 0 0" xyz="0 0 0"/>
      <geometry>
        <mesh filename="/home/dan/Projects/DrakeForks/VanillaDrakeWithIssue19842Mods/drake/examples/simple_gripper/robotiq_2f_140_gripper/collision/robotiq_arg2f_base_link.obj"/>
      </geometry>
      <drake:proximity_properties>
        <drake:rigid_hydroelastic/>
        <drake:hunt_crossley_dissipation value="100"/>
        <drake:relaxation_time value="100"/>
      </drake:proximity_properties>
    </collision>
  </link>
  <link name="left_outer_knuckle">
    <inertial>
      <origin rpy="0 0 0" xyz="-0.00020039 0.0090449 0.0078388"/>
      <mass value="0.008532"/>
      <inertia ixx="2.387e-06" ixy="-6.6175e-11" ixz="-1.1486e-11" iyy="1.3786e-06" iyz="-9.8111e-07" izz="1.4254e-06"/>
    </inertial>
    <visual>
      <origin rpy="0 0 0" xyz="0 0 0"/>
      <geometry>
        <mesh filename="/home/dan/Projects/DrakeForks/VanillaDrakeWithIssue19842Mods/drake/examples/simple_gripper/robotiq_2f_140_gripper/visual/robotiq_arg2f_140_outer_knuckle.obj"/>
      </geometry>
      <material name="">
        <color rgba="0.792156862745098 0.819607843137255 0.933333333333333 1"/>
      </material>
    </visual>
    <collision>
      <origin rpy="0 0 0" xyz="0 0 0"/>
      <geometry>
        <mesh filename="/home/dan/Projects/DrakeForks/VanillaDrakeWithIssue19842Mods/drake/examples/simple_gripper/robotiq_2f_140_gripper/collision/robotiq_arg2f_140_outer_knuckle.obj"/>
      </geometry>
      <drake:proximity_properties>
        <drake:rigid_hydroelastic/>
        <drake:hunt_crossley_dissipation value="100"/>
        <drake:relaxation_time value="100"/>
      </drake:proximity_properties>
    </collision>
  </link>
  <link name="left_outer_finger">
    <inertial>
      <origin rpy="0 0 0" xyz="-0.00021702 0.039217 -0.014782"/>
      <mass value="0.022614"/>
      <inertia ixx="1.6451e-05" ixy="-5.8739e-09" ixz="2.2297e-09" iyy="3.2034e-06" iyz="4.6625e-06" izz="1.5814e-05"/>
    </inertial>
    <visual>
      <origin rpy="0 0 0" xyz="0 0 0"/>
      <geometry>
        <mesh filename="/home/dan/Projects/DrakeForks/VanillaDrakeWithIssue19842Mods/drake/examples/simple_gripper/robotiq_2f_140_gripper/visual/robotiq_arg2f_140_outer_finger.obj"/>
      </geometry>
      <material name="">
        <color rgba="0.1 0.1 0.1 1"/>
      </material>
    </visual>
    <collision>
      <origin rpy="0 0 0" xyz="0 0 0"/>
      <geometry>
        <mesh filename="/home/dan/Projects/DrakeForks/VanillaDrakeWithIssue19842Mods/drake/examples/simple_gripper/robotiq_2f_140_gripper/collision/robotiq_arg2f_140_outer_finger.obj"/>
      </geometry>
      <drake:proximity_properties>
        <drake:rigid_hydroelastic/>
        <drake:hunt_crossley_dissipation value="100"/>
        <drake:relaxation_time value="100"/>
      </drake:proximity_properties>
    </collision>
  </link>
  <link name="left_inner_finger">
    <inertial>
      <origin rpy="0 0 0" xyz="-0.00020012 0.016693 -0.011922"/>
      <mass value="0.0104"/>
      <inertia ixx="2.34e-06" ixy="5.5159e-12" ixz="-7.4768e-12" iyy="7.6765e-07" iyz="5.1603e-07" izz="1.9464e-06"/>
    </inertial>
    <visual>
      <origin rpy="0 0 0" xyz="0 0 0"/>
      <geometry>
        <mesh filename="/home/dan/Projects/DrakeForks/VanillaDrakeWithIssue19842Mods/drake/examples/simple_gripper/robotiq_2f_140_gripper/visual/robotiq_arg2f_140_inner_finger.obj"/>
      </geometry>
      <material name="">
        <color rgba="0.1 0.1 0.1 1"/>
      </material>
    </visual>
    <collision>
      <origin rpy="0 0 0" xyz="0 0 0"/>
      <geometry>
        <mesh filename="/home/dan/Projects/DrakeForks/VanillaDrakeWithIssue19842Mods/drake/examples/simple_gripper/robotiq_2f_140_gripper/collision/robotiq_arg2f_140_inner_finger.obj"/>
      </geometry>
      <drake:proximity_properties>
        <drake:rigid_hydroelastic/>
        <drake:hunt_crossley_dissipation value="100"/>
        <drake:relaxation_time value="100"/>
      </drake:proximity_properties>
    </collision>
  </link>
  <link name="left_inner_finger_pad">
    <inertial>
      <inertia ixx="0" ixy="0" ixz="0" iyy="0" iyz="0" izz="0"/>
      <mass value="0"/>
      <origin rpy="0 0 0" xyz="0 0 0"/>
    </inertial>
    <visual>
      <origin rpy="0 0 0" xyz="0 0 0"/>
      <geometry>
        <box size="0.027 0.065 0.0075"/>
      </geometry>d
      <material name="">
        <color rgba="0.9 0.9 0.9 1"/>
      </material>
    </visual>
    <collision>
      <origin rpy="0 0 0" xyz="0 0 0"/>
      <geometry>
        <box size="0.03 0.07 0.0075"/>
      </geometry>
      <material name="">
        <color rgba="0.9 0.0 0.0 1"/>
      </material>
      <drake:proximity_properties>
        <drake:rigid_hydroelastic/>
        <drake:mesh_resolution_hint value="0.0001"/>
        <drake:hunt_crossley_dissipation value="100"/>
        <drake:relaxation_time value="100"/>
      </drake:proximity_properties>
    </collision>
  </link>
  <link name="left_inner_knuckle">
    <inertial>
      <origin rpy="0 0 0" xyz="0.0013408 0.048162 -0.0010672"/>
      <mass value="0.027118"/>
      <inertia ixx="2.7127e-05" ixy="-8.8385e-07" ixz="2.0258e-08" iyy="3.3337e-06" iyz="5.8643e-07" izz="2.9802e-05"/>
    </inertial>
    <visual>
      <origin rpy="0 0 0" xyz="0 0 0"/>
      <geometry>
        <mesh filename="/home/dan/Projects/DrakeForks/VanillaDrakeWithIssue19842Mods/drake/examples/simple_gripper/robotiq_2f_140_gripper/visual/robotiq_arg2f_140_inner_knuckle.obj"/>
      </geometry>
      <material name="">
        <color rgba="0.1 0.1 0.1 1"/>
      </material>
    </visual>
    <collision>
      <origin rpy="0 0 0" xyz="0 0 0"/>
      <geometry>
        <mesh filename="/home/dan/Projects/DrakeForks/VanillaDrakeWithIssue19842Mods/drake/examples/simple_gripper/robotiq_2f_140_gripper/collision/robotiq_arg2f_140_inner_knuckle.obj"/>
      </geometry>
      <drake:proximity_properties>
        <drake:rigid_hydroelastic/>
        <drake:hunt_crossley_dissipation value="100"/>
        <drake:relaxation_time value="100"/>
      </drake:proximity_properties>
    </collision>
  </link>
  <link name="right_outer_knuckle">
    <inertial>
      <origin rpy="0 0 0" xyz="-0.00020039 0.0090449 0.0078388"/>
      <mass value="0.008532"/>
      <inertia ixx="2.387e-06" ixy="-6.6175e-11" ixz="-1.1486e-11" iyy="1.3786e-06" iyz="-9.8111e-07" izz="1.4254e-06"/>
    </inertial>
    <visual>
      <origin rpy="0 0 0" xyz="0 0 0"/>
      <geometry>
        <mesh filename="/home/dan/Projects/DrakeForks/VanillaDrakeWithIssue19842Mods/drake/examples/simple_gripper/robotiq_2f_140_gripper/visual/robotiq_arg2f_140_outer_knuckle.obj"/>
      </geometry>
      <material name="">
        <color rgba="0.792156862745098 0.819607843137255 0.933333333333333 1"/>
      </material>
    </visual>
    <collision>
      <origin rpy="0 0 0" xyz="0 0 0"/>
      <geometry>
        <mesh filename="/home/dan/Projects/DrakeForks/VanillaDrakeWithIssue19842Mods/drake/examples/simple_gripper/robotiq_2f_140_gripper/collision/robotiq_arg2f_140_outer_knuckle.obj"/>
      </geometry>
      <drake:proximity_properties>
        <drake:rigid_hydroelastic/>
        <drake:hunt_crossley_dissipation value="100"/>
        <drake:relaxation_time value="100"/>
      </drake:proximity_properties>
    </collision>
  </link>
  <link name="right_outer_finger">
    <inertial>
      <origin rpy="0 0 0" xyz="-0.00021702 0.039217 -0.014782"/>
      <mass value="0.022614"/>
      <inertia ixx="1.6451e-05" ixy="-5.8739e-09" ixz="2.2297e-09" iyy="3.2034e-06" iyz="4.6625e-06" izz="1.5814e-05"/>
    </inertial>
    <visual>
      <origin rpy="0 0 0" xyz="0 0 0"/>
      <geometry>
        <mesh filename="/home/dan/Projects/DrakeForks/VanillaDrakeWithIssue19842Mods/drake/examples/simple_gripper/robotiq_2f_140_gripper/visual/robotiq_arg2f_140_outer_finger.obj"/>
      </geometry>
      <material name="">
        <color rgba="0.1 0.1 0.1 1"/>
      </material>
    </visual>
    <collision>
      <origin rpy="0 0 0" xyz="0 0 0"/>
      <geometry>
        <mesh filename="/home/dan/Projects/DrakeForks/VanillaDrakeWithIssue19842Mods/drake/examples/simple_gripper/robotiq_2f_140_gripper/collision/robotiq_arg2f_140_outer_finger.obj"/>
      </geometry>
      <drake:proximity_properties>
        <drake:rigid_hydroelastic/>
        <drake:hunt_crossley_dissipation value="100"/>
        <drake:relaxation_time value="100"/>
      </drake:proximity_properties>
    </collision>
  </link>
  <link name="right_inner_finger">
    <inertial>
      <origin rpy="0 0 0" xyz="-0.00020012 0.016693 -0.011922"/>
      <mass value="0.0104"/>
      <inertia ixx="2.34e-06" ixy="5.5159e-12" ixz="-7.4768e-12" iyy="7.6765e-07" iyz="5.1603e-07" izz="1.9464e-06"/>
    </inertial>
    <visual>
      <origin rpy="0 0 0" xyz="0 0 0"/>
      <geometry>
        <mesh filename="/home/dan/Projects/DrakeForks/VanillaDrakeWithIssue19842Mods/drake/examples/simple_gripper/robotiq_2f_140_gripper/visual/robotiq_arg2f_140_inner_finger.obj"/>
      </geometry>
      <material name="">
        <color rgba="0.1 0.1 0.1 1"/>
      </material>
    </visual>
    <collision>
      <origin rpy="0 0 0" xyz="0 0 0"/>
      <geometry>
        <mesh filename="/home/dan/Projects/DrakeForks/VanillaDrakeWithIssue19842Mods/drake/examples/simple_gripper/robotiq_2f_140_gripper/collision/robotiq_arg2f_140_inner_finger.obj"/>
      </geometry>
      <drake:proximity_properties>
        <drake:rigid_hydroelastic/>
        <drake:hunt_crossley_dissipation value="100"/>
        <drake:relaxation_time value="100"/>
      </drake:proximity_properties>
    </collision>
  </link>
  <link name="right_inner_finger_pad">
    <inertial>
      <inertia ixx="0" ixy="0" ixz="0" iyy="0" iyz="0" izz="0"/>
      <mass value="0"/>
      <origin rpy="0 0 0" xyz="0 0 0"/>
    </inertial>
    <visual>
      <origin rpy="0 0 0" xyz="0 0 0"/>
      <geometry>
        <box size="0.027 0.065 0.0075"/>
      </geometry>
      <material name="">
        <color rgba="0.9 0.9 0.9 1"/>
      </material>
    </visual>
    <collision>
      <origin rpy="0 0 0" xyz="0 0 0"/>
      <geometry>
        <box size="0.03 0.07 0.0075"/>
      </geometry>
      <material name="">
        <color rgba="0.9 0.0 0.0 1"/>
      </material>
      <drake:proximity_properties>
        <drake:rigid_hydroelastic/>
        <drake:mesh_resolution_hint value="0.0001"/>
        <drake:hunt_crossley_dissipation value="100"/>
        <drake:relaxation_time value="100"/>
      </drake:proximity_properties>
    </collision>
  </link>
  <link name="right_inner_knuckle">
    <inertial>
      <origin rpy="0 0 0" xyz="0.0013408 0.048162 -0.0010672"/>
      <mass value="0.027118"/>
      <inertia ixx="2.7127e-05" ixy="-8.8385e-07" ixz="2.0258e-08" iyy="3.3337e-06" iyz="5.8643e-07" izz="2.9802e-05"/>
    </inertial>
    <visual>
      <origin rpy="0 0 0" xyz="0 0 0"/>
      <geometry>
        <mesh filename="/home/dan/Projects/DrakeForks/VanillaDrakeWithIssue19842Mods/drake/examples/simple_gripper/robotiq_2f_140_gripper/visual/robotiq_arg2f_140_inner_knuckle.obj"/>
      </geometry>
      <material name="">
        <color rgba="0.1 0.1 0.1 1"/>
      </material>
    </visual>
    <collision>
      <origin rpy="0 0 0" xyz="0 0 0"/>
      <geometry>
        <mesh filename="/home/dan/Projects/DrakeForks/VanillaDrakeWithIssue19842Mods/drake/examples/simple_gripper/robotiq_2f_140_gripper/collision/robotiq_arg2f_140_inner_knuckle.obj"/>
      </geometry>
      <drake:proximity_properties>
        <drake:rigid_hydroelastic/>
        <drake:hunt_crossley_dissipation value="100"/>
        <drake:relaxation_time value="100"/>
      </drake:proximity_properties>
    </collision>
  </link>
  <joint name="finger_joint" type="revolute">
    <origin rpy="2.29579632679 0 0" xyz="0 -0.030601 0.054905"/>
    <parent link="robotiq_arg2f_base_link"/>
    <child link="left_outer_knuckle"/>
    <axis xyz="-1 0 0"/>
    <limit effort="1000" lower="0" upper="0.7" velocity="2.0"/>
  </joint>
  <joint name="left_outer_finger_joint" type="fixed">
    <origin rpy="0 0 0" xyz="0 0.01821998610742 0.0260018192872234"/>
    <parent link="left_outer_knuckle"/>
    <child link="left_outer_finger"/>
    <axis xyz="1 0 0"/>
  </joint>
  <joint name="left_inner_knuckle_joint" type="revolute">
    <origin rpy="2.29579632679 0 0.0" xyz="0 -0.0127 0.06142"/>
    <parent link="robotiq_arg2f_base_link"/>
    <child link="left_inner_knuckle"/>
    <axis xyz="1 0 0"/>
    <limit effort="1000" lower="-0.8757" upper="0.8757" velocity="2.0"/>
    <mimic joint="finger_joint" multiplier="-1" offset="0"/>
  </joint>
  <joint name="left_inner_finger_joint" type="revolute">
    <origin rpy="-0.725 0 0" xyz="0 0.0817554015893473 -0.0282203446692936"/>
    <parent link="left_outer_finger"/>
    <child link="left_inner_finger"/>
    <axis xyz="1 0 0"/>
    <limit effort="1000" lower="-0.8757" upper="0.8757" velocity="2.0"/>
    <mimic joint="finger_joint" multiplier="1" offset="0"/>
  </joint>
  <joint name="left_inner_finger_pad_joint" type="fixed">
    <origin rpy="0 0 0" xyz="0 0.0457554015893473 -0.0272203446692936"/>
    <parent link="left_inner_finger"/>
    <child link="left_inner_finger_pad"/>
    <axis xyz="0 0 1"/>
  </joint>
  <joint name="right_outer_knuckle_joint" type="revolute">
    <origin rpy="2.29579632679 0 3.14159265359" xyz="0 0.030601 0.054905"/>
    <parent link="robotiq_arg2f_base_link"/>
    <child link="right_outer_knuckle"/>
    <axis xyz="1 0 0"/>
    <limit effort="1000" lower="-0.725" upper="0.725" velocity="2.0"/>
    <mimic joint="finger_joint" multiplier="-1" offset="0"/>
  </joint>
  <joint name="right_outer_finger_joint" type="fixed">
    <origin rpy="0 0 0" xyz="0 0.01821998610742 0.0260018192872234"/>
    <parent link="right_outer_knuckle"/>
    <child link="right_outer_finger"/>
    <axis xyz="1 0 0"/>
  </joint>
  <joint name="right_inner_knuckle_joint" type="revolute">
    <origin rpy="2.29579632679 0 -3.14159265359" xyz="0 0.0127 0.06142"/>
    <parent link="robotiq_arg2f_base_link"/>
    <child link="right_inner_knuckle"/>
    <axis xyz="1 0 0"/>
    <limit effort="1000" lower="-0.8757" upper="0.8757" velocity="2.0"/>
    <mimic joint="finger_joint" multiplier="-1" offset="0"/>
  </joint>
  <joint name="right_inner_finger_joint" type="revolute">
    <origin rpy="-0.725 0 0" xyz="0 0.0817554015893473 -0.0282203446692936"/>
    <parent link="right_outer_finger"/>
    <child link="right_inner_finger"/>
    <axis xyz="1 0 0"/>
    <limit effort="1000" lower="-0.8757" upper="0.8757" velocity="2.0"/>
    <mimic joint="finger_joint" multiplier="1" offset="0"/>
  </joint>
  <joint name="right_inner_finger_pad_joint" type="fixed">
    <origin rpy="0 0 0" xyz="0 0.0457554015893473 -0.0272203446692936"/>
    <parent link="right_inner_finger"/>
    <child link="right_inner_finger_pad"/>
    <axis xyz="0 0 1"/>
  </joint>
  <transmission name="finger_joint_trans">
    <type>transmission_interface/SimpleTransmission</type>
    <joint name="finger_joint">
      <hardwareInterface>PositionJointInterface</hardwareInterface>
    </joint>
    <actuator name="finger_joint_motor">
      <mechanicalReduction>1</mechanicalReduction>
      <drake:rotor_inertia value="5e-3"/>
      <drake:gear_ratio value="20"/>
    </actuator>
  </transmission>
    <drake:collision_filter_group name="finger_1">
      <drake:member link="left_outer_knuckle"/>
      <drake:member link="left_outer_finger"/>
      <drake:member link="left_inner_finger"/>
      <drake:member link="left_inner_knuckle"/>
      <drake:ignored_collision_filter_group name="finger_1"/>
    </drake:collision_filter_group>
    <drake:collision_filter_group name="finger_2">
      <drake:member link="right_outer_knuckle"/>
      <drake:member link="right_outer_finger"/>
      <drake:member link="right_inner_finger"/>
      <drake:member link="right_inner_knuckle"/>
      <drake:ignored_collision_filter_group name="finger_2"/>
    </drake:collision_filter_group>
</robot>
